Workbook

Sheet 데이터 만드는 순서 및 담당자
A1: ***의존관계 확인*** | B1: 테이블 | C1: 삽입단계 | D1: 분류 | E1: 담당자 | F1: 클라우드에 올렸는지 여부 | H1: 분류 | I1: 담당자
A2: 1. **tblSubject** - 과목 정보 | B2: tblSubject | C2: 1 | D2: 과정 | E2: =iferror(VLOOKUP(D2,$H$1:$I$7,2,0),"") -> 구윤 | F2: INSERT | H2: 학생 | I2: 재만, 홍건
A3: 2. **tblCompletionStatus** - 수료 상태 | B3: tblCompletionStatus | C3: 1 | D3: 학생 | E3: =iferror(VLOOKUP(D3,$H$1:$I$7,2,0),"") -> 재만, 홍건 | F3: INSERT | H3: 시험 | I3: 서진
A4: 3. **tblAttendanceCategory** - 출석 카테고리 | B4: tblAttendanceCategory | C4: 1 | D4: 출결 | E4: =iferror(VLOOKUP(D4,$H$1:$I$7,2,0),"") -> 보영 | F4: INSERT | H4: 기타 | I4: 서진
A5: 4. **tblTextBook** - 교재 정보 | B5: tblTextBook | C5: 1 | D5: 과정 | E5: =iferror(VLOOKUP(D5,$H$1:$I$7,2,0),"") -> 구윤 | F5: INSERT | H5: 출결 | I5: 보영
A6: 5. **tblQuestionBank** - 문제은행 | B6: tblQuestionBank | C6: 1 | D6: 시험 | E6: =iferror(VLOOKUP(D6,$H$1:$I$7,2,0),"") -> 서진 | F6: INSERT | H6: 게시판 | I6: 보영
A7: 6. **tblApplicant** - 지원자 정보 | B7: tblApplicant | C7: 1 | D7: 학생 | E7: =iferror(VLOOKUP(D7,$H$1:$I$7,2,0),"") -> 재만, 홍건 | F7: INSERT | H7: 과정 | I7: 구윤
A8: 7. **tblReward** - 상품 정보 | B8: tblReward | C8: 1 | D8: 기타 | E8: =iferror(VLOOKUP(D8,$H$1:$I$7,2,0),"") -> 서진 | F8: INSERT
A9: 8. **tblAdmin** - 관리자 정보 | B9: tblAdmin | C9: 1 | D9: 기타 | E9: =iferror(VLOOKUP(D9,$H$1:$I$7,2,0),"") -> 서진 | F9: INSERT
A10: 9. **tblAnswerStatus** - 답변 상태 | B10: tblAnswerStatus | C10: 1 | D10: 게시판 | E10: =iferror(VLOOKUP(D10,$H$1:$I$7,2,0),"") -> 보영 | F10: INSERT
A11: 10. **tblTeacher** - 강사 정보 | B11: tblTeacher | C11: 1 | D11: 과정 | E11: =iferror(VLOOKUP(D11,$H$1:$I$7,2,0),"") -> 구윤 | F11: INSERT
A12: 11. **tblClassroom** - 강의실 정보 | B12: tblClassroom | C12: 1 | D12: 과정 | E12: =iferror(VLOOKUP(D12,$H$1:$I$7,2,0),"") -> 구윤 | F12: INSERT
A13: 12. **tblExamConversionRatio** - 시험 배점 (의존 없음) | B13: tblExamConversionRatio | C13: 1 | D13: 기타 | E13: =iferror(VLOOKUP(D13,$H$1:$I$7,2,0),"") -> 서진 | F13: INSERT
A14: 39. **tblHoliday** 공휴일 관리 (의존 없음) | B14: tblHoliday | C14: 1 | D14: 출결 | E14: 구윤 | F14: INSERT | G14: 24년~26년 공휴일 정보입력
E15: =iferror(VLOOKUP(D15,$H$1:$I$7,2,0),"")
A16: ## 2단계: 1단계 테이블에 의존하는 자식 테이블들 | E16: =iferror(VLOOKUP(D16,$H$1:$I$7,2,0),"")
A17: 13. **tblInterviewedStudent** - (tblApplicant 의존) | B17: tblInterviewedStudent | C17: 2 | D17: 학생 | E17: =iferror(VLOOKUP(D17,$H$1:$I$7,2,0),"") -> 재만, 홍건 | F17: INSERT
A18: 14. **tblLocker** - (tblClassroom 의존) | B18: tblLocker | C18: 2 | D18: 과정 | E18: =iferror(VLOOKUP(D18,$H$1:$I$7,2,0),"") -> 구윤 | F18: INSERT
A19: 15. **tblExamSheet** - (tblSubject 의존) | B19: tblExamSheet | C19: 2 | D19: 시험 | E19: =iferror(VLOOKUP(D19,$H$1:$I$7,2,0),"") -> 서진 | F19: INSERT
A20: 16. **tblQnaAnswer** - (tblTeacher 의존) | B20: tblQnaAnswer | C20: 2 | D20: 게시판 | E20: =iferror(VLOOKUP(D20,$H$1:$I$7,2,0),"") -> 보영 | F20: INSERT
E21: =iferror(VLOOKUP(D21,$H$1:$I$7,2,0),"")
A22: ## 3단계: 2단계 테이블에 의존하는 자식 테이블들 | E22: =iferror(VLOOKUP(D22,$H$1:$I$7,2,0),"")
A23: 17. **tblPassedStudent** - (tblInterviewedStudent 의존) | B23: tblPassedStudent | C23: 3 | D23: 학생 | E23: =iferror(VLOOKUP(D23,$H$1:$I$7,2,0),"") -> 재만, 홍건 | F23: INSERT
A24: 18. **tblOpenCourse** - (tblClassroom, tblTeacher 의존) | B24: tblOpenCourse | C24: 3 | D24: 과정 | E24: =iferror(VLOOKUP(D24,$H$1:$I$7,2,0),"") -> 구윤 | F24: INSERT
A25: 19. **tblExamInfo** - (tblExamSheet 의존) | B25: tblExamInfo | C25: 3 | D25: 시험 | E25: =iferror(VLOOKUP(D25,$H$1:$I$7,2,0),"") -> 서진 | F25: INSERT
E26: =iferror(VLOOKUP(D26,$H$1:$I$7,2,0),"")
A27: ## 4단계: 3단계 테이블에 의존하는 자식 테이블들 | E27: =iferror(VLOOKUP(D27,$H$1:$I$7,2,0),"")
A28: 20. **tblStudent** - (tblPassedStudent 의존) | B28: tblStudent | C28: 4 | D28: 학생 | E28: =iferror(VLOOKUP(D28,$H$1:$I$7,2,0),"") -> 재만, 홍건 | F28: INSERT
A29: 21. **tblDayAttendanceLog** - (tblStudent 의존) | B29: tblDayAttendanceLog | C29: 4 | D29: 출결 | E29: =iferror(VLOOKUP(D29,$H$1:$I$7,2,0),"") -> 보영 | F29: INSERT
A30: 22. **tblReviewRecord** - (tblStudent 의존) | B30: tblReviewRecord | C30: 4 | D30: 게시판 | E30: =iferror(VLOOKUP(D30,$H$1:$I$7,2,0),"") -> 보영 | F30: INSERT
A31: 23. **tblBookReceipt** - (tblOpenCourse, tblStudent, tblTextBook 의존) | B31: tblBookReceipt | C31: 4 | D31: 과정 | E31: =iferror(VLOOKUP(D31,$H$1:$I$7,2,0),"") -> 구윤 | F31: INSERT
A32: 24. **tblQnaAndCounselBoard** - (tblStudent, tblQnaAnswer, tblAnswerStatus 의존) | B32: tblQnaAndCounselBoard | C32: 4 | D32: 게시판 | E32: =iferror(VLOOKUP(D32,$H$1:$I$7,2,0),"") -> 보영 | F32: INSERT
A33: 25. **tblPracticalExamResult** - (tblStudent, tblExamInfo 의존) | B33: tblPracticalExamResult | C33: 4 | D33: 시험 | E33: =iferror(VLOOKUP(D33,$H$1:$I$7,2,0),"") -> 서진 | F33: INSERT
A34: 26. **tblStudentTotalScore** - (tblStudent 의존) | B34: tblStudentTotalScore | C34: 4 | D34: 시험 | E34: =iferror(VLOOKUP(D34,$H$1:$I$7,2,0),"") -> 서진 | F34: INSERT
A35: 27. **tblWrittenExamResult** - (tblStudent, tblExamInfo 의존) | B35: tblWrittenExamResult | C35: 4 | D35: 시험 | E35: =iferror(VLOOKUP(D35,$H$1:$I$7,2,0),"") -> 서진 | F35: INSERT
A36: 28. **tblCourseApplicationRecord** - (tblApplicant 의존) | B36: tblCourseApplicationRecord | C36: 4 | D36: 학생 | E36: =iferror(VLOOKUP(D36,$H$1:$I$7,2,0),"") -> 재만, 홍건 | F36: INSERT
A37: 29. **tblStudentCompletionStatus** - (tblStudent, tblCompletionStatus 의존) | B37: tblStudentCompletionStatus | C37: 4 | D37: 학생 | E37: =iferror(VLOOKUP(D37,$H$1:$I$7,2,0),"") -> 재만, 홍건 | F37: INSERT
A38: 30. **tblExamQuestionLink** - (tblExamSheet, tblQuestionBank 의존) | B38: tblExamQuestionLink | C38: 4 | D38: 시험 | E38: =iferror(VLOOKUP(D38,$H$1:$I$7,2,0),"") -> 서진 | F38: INSERT
A39: 31. **tblTeacherSubject** - (tblTeacher, tblSubject 의존) | B39: tblTeacherSubject | C39: 4 | D39: 과정 | E39: =iferror(VLOOKUP(D39,$H$1:$I$7,2,0),"") -> 구윤 | F39: INSERT
A40: 32. **tblJobPlacement** - (tblStudent 의존) | B40: tblJobPlacement | C40: 4 | D40: 기타 | E40: =iferror(VLOOKUP(D40,$H$1:$I$7,2,0),"") -> 서진 | F40: INSERT
...

Sheet 데이터 insert참고내용
A1: 1 | B1: 외래키 무시하고 테이블 삭제 방법 | C1: DROP TABLE 테이블명 CASCADE CONSTRAINTS; | D1: 제일앞에 등호(=) 직접추가 컬럼네개짜리 예시 (숫자열, 문자열, 문자열, 숫자열) | E1: 숫자형식 컬럼 추가시 숫자 추가시 복붙(알파벳을 열번호에 맞게 수정 후 사용) | F1: 문자형식 컬럼 추가시 문자열 추가시 복붙(알파벳을 열번호에 맞게 수정후 사용)
A2: 2 | B2: insert 자동 함수 | C2: 인서트문 삽입하는 함수!!!!! 앞에 = 붙이기 / 본인 데이터 열 수 만큼 A2 B2 C2 추가 혹은 삭제 | D2: "INSERT INTO 테이블명 VALUES (" & A2 & ", '" & B2 & "', '" & C2 & "', " & D2 & ");" | E2: ," & E2 & " | F2: ,'" & E2 & "'
A3: 0 | B3: &' 문자열 넣는법 | C3: SET DEFINE OFF; | D3: <<-- 실행하면 세션이 종료되는 순간까지 & 문자열 입력가능 SQL Developer를 껐거나, 연결 탭을 닫거나, 재접속했거나 → 다시 기본값인 SET DEFINE ON;

Sheet 부모
B1: 부모 | C1: 한글이름 | D1: 부모 | E1: 분류 | F1: 담당 | G1: 상태 | I1: 분류 | J1: 갯수
A2: 2 | B2: tblCompletionStatus - 수료 상태 | D2: 부모 | E2: 학생 | F2: 홍건 | G2: 클라우드 인서트 완료 | H2: 1 | I2: {=unique(F2:F12)} -> 홍건 | J2: =COUNTIF($E$2:$E$100,I2) -> 0
A3: 6 | B3: tblApplicant - 지원자 정보(300명) | D3: 부모 | E3: 학생 | F3: 재만 | G3: 클라우드 인서트 완료 | H3: 2 | I3: 재만 | J3: =COUNTIF($E$2:$E$100,I3) -> 0
A4: 3 | B4: tblAttendanceCategory - 출석 카테고리 | D4: 부모 | E4: 출결 | H4: 3 | J4: =COUNTIF($E$2:$E$100,I4) -> 0
A5: 5 | B5: tblQuestionBank - 문제 은행 | D5: 부모 | E5: 시험 | H5: 4 | J5: =COUNTIF($E$2:$E$100,I5) -> 0
A6: 7 | B6: tblReward - 보상정보 | C6: 보상정보 | D6: 부모 | E6: 기타 | H6: 5 | J6: =COUNTIF($E$2:$E$100,I6) -> 0
A7: 11 | B7: tblExamConversionRatio - 시험 비율 (PK 없음, 자식 없음) | D7: 부모 | E7: 기타 | H7: 6 | J7: =COUNTIF($E$2:$E$100,I7) -> 0
A8: 8 | B8: tblAdmin - 관리자 정보 | D8: 부모 | E8: 기타 | H8: 7 | J8: =COUNTIF($E$2:$E$100,I8) -> 0
A9: 1 | B9: tblSubject - 과목 정보 | D9: 부모 | E9: 과정 | G9: 클라우드 인서트 완료 | H9: 8 | I9: 기타 | J9: =COUNTIF($E$2:$E$100,I9) -> 3
A10: 4 | B10: tblTextBook - 교재 정보 | D10: 부모 | E10: 과정 | G10: 클라우드 인서트 완료
A11: 9 | B11: tblAnswerStatus - 답변 상태 | D11: 부모 | E11: 게시판
A12: 10 | B12: tblTeacher - 강사 정보 | D12: 부모 | E12: 교사 | G12: 클라우드 인서트 완료
H14: 부모+자식 분류 | I14: 갯수 | K14: 학생
A15: 인서트문 삽입하는 함수!!!!! 앞에 = 붙이기 / 본인 데이터 열 수 만큼 A2 B2 C2 추가 혹은 삭제 / 안되면 디코나 카톡으로 문의 | G15: 1 | H15: {=UNIQUE(K14:K29)} -> 학생 | I15: =I2+'자식'!J2 -> #VALUE! | K15: 출결
G16: 2 | H16: 출결 | I16: =I3+'자식'!J3 -> #VALUE! | K16: 시험
A17: "INSERT INTO 테이블명 VALUES (" & A2 & ", '" & B2 & "', '" & C2 & "', " & D2 & ");" | G17: 3 | H17: 시험 | I17: =I4+'자식'!J4 -> 6 | K17: 사후처리
G18: 4 | H18: 사후처리 | I18: ='자식'!J5 -> 1 | K18: 교사
G19: 5 | H19: 교사 | I19: =I10+'자식'!J6+'자식'!J7 -> 5 | K19: 과정
G20: 6 | H20: 과정 | I20: =I8+'자식'!J7 -> 4 | K20: 게시판
G21: 7 | H21: 게시판 | I21: =I9+'자식'!J8 -> #VALUE! | K21: 학생
G22: 8 | H22: 보상 | I22: =I5 | K22: 출결
G23: 9 | H23: 독립 | I23: 1 | K23: 시험
G24: 10 | H24: 관리자 | I24: =I7 | K24: 보상
G25: 11 | H25: 기타 | I25: 3 | K25: 독립
K26: 관리자
K27: 과정
K28: 게시판
K29: 기타
M33: ='자식'!N20
G37: 데이터양많은순 | H37: AB | I37: 학생 | J37: 9 | K37: 재만,홍건
H38: C | I38: 시험/독립/보상/관리자/기타 | K38: 서진
H39: D | I39: 출결/사후처리/게시판 | K39: 보영
H40: E | I40: 과정/교사 | J40: 8 | K40: 구윤

Sheet 자식
B1: 자식 | C1: 한글이름 | D1: 부모 | E1: 분류 | F1: 담당 | G1: 상태
A2: 1 | B2: tblInterviewedStudent - 면접완료자 (tblApplicant 참조) | D2: 자식 | E2: 학생 | F2: 재만 | G2: 완 | H2: 1 | I2: {=unique(E2:E27)} -> 학생 | J2: =COUNTIF($E$2:$E$100,I2) -> 7
A3: 2 | B3: tblPassedStudent - 합격자 (tblInterviewedStudent 참조) | D3: 자식 | E3: 학생 | F3: 재만 | H3: 2 | I3: 출결 | J3: =COUNTIF($E$2:$E$100,I3) -> 2
A4: 3 | B4: tblStudent - 수강생 (tblPassedStudent 참조) | D4: 자식 | E4: 학생 | H4: 3 | I4: 시험 | J4: =COUNTIF($E$2:$E$100,I4) -> 6
A5: 18 | B5: tblCourseApplicationRecord - 수강신청내역 (tblApplicant 참조) | D5: 자식 | E5: 학생 | F5: 홍건 | H5: 4 | I5: 기타 | J5: =COUNTIF($E$2:$E$100,I5) -> 1
A6: 19 | B6: tblStudentCompletionStatus - 학생 수료 상태 (tblStudent, tblCompletionStatus 참조) | D6: 자식 | E6: 학생 | H6: 5 | I6: 교사 | J6: =COUNTIF($E$2:$E$100,I6) -> 1
A7: 23 | B7: tblCourseStudentMapping - 과정 학생 매핑 (tblStudent, tblOpenCourse, tblLocker 참조) | D7: 자식 | E7: 학생 | H7: 6 | I7: 과정 | J7: =COUNTIF($E$2:$E$100,I7) -> 4
A8: 26 | B8: tblOutstandingStudentList - 우수 학생 목록 (tblStudent, tblReward 참조) | D8: 자식 | E8: 학생 | H8: 7 | I8: 게시판 | J8: =COUNTIF($E$2:$E$100,I8) -> 5
A9: 10 | B9: tblDayAttendanceLog - 일일 출석 로그 (tblStudent 참조) | D9: 자식 | E9: 출결
A10: 24 | B10: tblAttendanceScore - 출석 점수 (tblDayAttendanceLog, tblAttendanceCategory 참조) | D10: 자식 | E10: 출결
A11: 7 | B11: tblExamSheet - 시험지 (tblSubject 참조) | D11: 자식 | E11: 시험
A12: 8 | B12: tblExamInfo - 시험 정보 (tblExamSheet 참조) | D12: 자식 | E12: 시험
A13: 14 | B13: tblPracticalExamResult - 실기 시험 결과 (tblStudent, tblExamInfo 참조) | D13: 자식 | E13: 시험
A14: 15 | B14: tblStudentTotalScore - 학생 총점 (tblStudent 참조) | D14: 자식 | E14: 시험
A15: 17 | B15: tblWrittenExamResult - 필기 시험 결과 (tblStudent, tblExamInfo 참조) | D15: 자식 | E15: 시험
A16: 20 | B16: tblExamQuestionLink - 시험지별문제 (tblExamSheet, tblQuestionBank 참조) | D16: 자식 | E16: 시험
A17: 22 | B17: tblJobPlacement - 취업 배치 (tblStudent 참조) | D17: 자식 | E17: 기타
A18: 21 | B18: tblTeacherSubject - 강사 과목 (tblTeacher, tblSubject 참조) | D18: 자식 | E18: 교사 | F18: 클라우드 인서트 완료
A19: 4 | B19: tblClassroom - 교실 | D19: 자식 | E19: 과정 | F19: 클라우드 인서트 완료
A20: 5 | B20: tblLocker - 사물함 (tblClassroom 참조) | D20: 자식 | E20: 과정
A21: 6 | B21: tblOpenCourse - 개설 과정 (tblClassroom, tblTeacher 참조) | D21: 자식 | E21: 과정
A22: 12 | B22: tblBookReceipt - 교재 수령 (tblOpenCourse, tblStudent, tblTextBook 참조) | D22: 자식 | E22: 과정
A23: 9 | B23: tblQnaAnswer - Q&A 답변 (tblTeacher 참조) | D23: 자식 | E23: 게시판
A24: 11 | B24: tblReviewRecord - 리뷰 기록 (tblStudent 참조) | D24: 자식 | E24: 게시판
A25: 13 | B25: tblQnaAndCounselBoard - Q&A 상담 게시판 (tblStudent, tblQnaAnswer, tblAnswerStatus 참조) | D25: 자식 | E25: 게시판 | G25: 11
A26: 16 | B26: tblQnAdeleteLog - Q&A 삭제 로그 (tblAdmin, tblQnaAndCounselBoard 참조) | D26: 자식 | E26: 게시판
A27: 25 | B27: tblReviewBoard - 리뷰 게시판 (tblReviewRecord 참조) | D27: 자식 | E27: 게시판
G37: 데이터양많은순

Sheet 출결유형
A1: 출결 종류 | B1: 출결배점 (이름변경) | C1: 출결 유형 번호 | E1: 출결유형 번호 | L1: 출결 종류 | M1: 출결유형 번호
A2: 출석 | B2: 0 | C2: seqAttendanceCategory.nextval | E2: 1 | F2: ="INSERT INTO tblAttendanceCategory VALUES (" & C2 & ", " & A2 & ", " & B2 & ");" -> INSERT INTO tblAttendanceCategory VALUES (seqAttendanceCategory.nextval, 출석, 0); | L2: 출석 | M2: 1
A3: 결석 | B3: -1 | C3: seqAttendanceCategory.nextval | E3: 2 | F3: ="INSERT INTO tblAttendanceCategory VALUES (" & C3 & ", " & A3 & ", " & B3 & ");" -> INSERT INTO tblAttendanceCategory VALUES (seqAttendanceCategory.nextval, 결석, -1); | L3: 결석 | M3: 2
A4: 조퇴 | B4: -0.25 | C4: seqAttendanceCategory.nextval | E4: 3 | F4: ="INSERT INTO tblAttendanceCategory VALUES (" & C4 & ", " & A4 & ", " & B4 & ");" -> INSERT INTO tblAttendanceCategory VALUES (seqAttendanceCategory.nextval, 조퇴, -0.25); | L4: 조퇴 | M4: 3
A5: 출석인정 | B5: 0 | C5: seqAttendanceCategory.nextval | E5: 4 | F5: ="INSERT INTO tblAttendanceCategory VALUES (" & C5 & ", " & A5 & ", " & B5 & ");" -> INSERT INTO tblAttendanceCategory VALUES (seqAttendanceCategory.nextval, 출석인정, 0); | L5: 출석인정 | M5: 4
A6: 지각 | B6: -0.25 | C6: seqAttendanceCategory.nextval | E6: 5 | F6: ="INSERT INTO tblAttendanceCategory VALUES (" & C6 & ", " & A6 & ", " & B6 & ");" -> INSERT INTO tblAttendanceCategory VALUES (seqAttendanceCategory.nextval, 지각, -0.25); | L6: 지각 | M6: 5
F8: COMMIT;
A12: 출결상태 | B12: 조건
A13: 결석 | B13: - 입실시간이 NULL 또는 퇴실시간이 NULL - 수업시간 < 4시간
A14: 조퇴 | B14: - 수업시간 ≥ 4시간 이지만 - 퇴실시간 < 17:50:00
A15: 지각 | B15: - 입실시간 >09:00:00 - 퇴실시간은 있고 수업시간 ≥ 4시간 AND 퇴실 ≥ 17:50:00
A16: 출석 | B16: - 입실시간 < 09:00:00 - 퇴실시간 ≥ 17:50:00 - 수업시간 ≥ 4시간

Sheet 출결점수
A1: 출결점수번호 | B1: 출결점수 | C1: 출결일지번호 | D1: 출결유형번호 | E1: 출결상태
A2: seqAttendanceScore.nextval | B2: =iferror(VLOOKUP(E2,'출결유형'!$A:$C,2,0),"") -> -0.25 | C2: 1 | D2: =iferror(VLOOKUP(E2,'출결유형'!$L:$M,2,0),"") -> 5 | E2: 지각 | G2: ="INSERT INTO tblAttendanceScore VALUES (" & A2 & ", " & B2 & ", " & C2 & ", " & D2 & ");" -> INSERT INTO tblAttendanceScore VALUES (seqAttendanceScore.nextval, -0.25, 1, 5);
A3: seqAttendanceScore.nextval | B3: =iferror(VLOOKUP(E3,'출결유형'!$A:$C,2,0),"") -> 0 | C3: 2 | D3: =iferror(VLOOKUP(E3,'출결유형'!$L:$M,2,0),"") -> 1 | E3: 출석 | G3: ="INSERT INTO tblAttendanceScore VALUES (" & A3 & ", " & B3 & ", " & C3 & ", " & D3 & ");" -> INSERT INTO tblAttendanceScore VALUES (seqAttendanceScore.nextval, 0, 2, 1);
A4: seqAttendanceScore.nextval | B4: =iferror(VLOOKUP(E4,'출결유형'!$A:$C,2,0),"") -> -0.25 | C4: 3 | D4: =iferror(VLOOKUP(E4,'출결유형'!$L:$M,2,0),"") -> 5 | E4: 지각 | G4: ="INSERT INTO tblAttendanceScore VALUES (" & A4 & ", " & B4 & ", " & C4 & ", " & D4 & ");" -> INSERT INTO tblAttendanceScore VALUES (seqAttendanceScore.nextval, -0.25, 3, 5);
A5: seqAttendanceScore.nextval | B5: =iferror(VLOOKUP(E5,'출결유형'!$A:$C,2,0),"") -> 0 | C5: 4 | D5: =iferror(VLOOKUP(E5,'출결유형'!$L:$M,2,0),"") -> 1 | E5: 출석 | G5: ="INSERT INTO tblAttendanceScore VALUES (" & A5 & ", " & B5 & ", " & C5 & ", " & D5 & ");" -> INSERT INTO tblAttendanceScore VALUES (seqAttendanceScore.nextval, 0, 4, 1);
A6: seqAttendanceScore.nextval | B6: =iferror(VLOOKUP(E6,'출결유형'!$A:$C,2,0),"") -> 0 | C6: 5 | D6: =iferror(VLOOKUP(E6,'출결유형'!$L:$M,2,0),"") -> 1 | E6: 출석 | G6: ="INSERT INTO tblAttendanceScore VALUES (" & A6 & ", " & B6 & ", " & C6 & ", " & D6 & ");" -> INSERT INTO tblAttendanceScore VALUES (seqAttendanceScore.nextval, 0, 5, 1);
A7: seqAttendanceScore.nextval | B7: =iferror(VLOOKUP(E7,'출결유형'!$A:$C,2,0),"") -> 0 | C7: 6 | D7: =iferror(VLOOKUP(E7,'출결유형'!$L:$M,2,0),"") -> 1 | E7: 출석 | G7: ="INSERT INTO tblAttendanceScore VALUES (" & A7 & ", " & B7 & ", " & C7 & ", " & D7 & ");" -> INSERT INTO tblAttendanceScore VALUES (seqAttendanceScore.nextval, 0, 6, 1);
A8: seqAttendanceScore.nextval | B8: =iferror(VLOOKUP(E8,'출결유형'!$A:$C,2,0),"") -> 0 | C8: 7 | D8: =iferror(VLOOKUP(E8,'출결유형'!$L:$M,2,0),"") -> 1 | E8: 출석 | G8: ="INSERT INTO tblAttendanceScore VALUES (" & A8 & ", " & B8 & ", " & C8 & ", " & D8 & ");" -> INSERT INTO tblAttendanceScore VALUES (seqAttendanceScore.nextval, 0, 7, 1);
A9: seqAttendanceScore.nextval | B9: =iferror(VLOOKUP(E9,'출결유형'!$A:$C,2,0),"") -> -0.25 | C9: 8 | D9: =iferror(VLOOKUP(E9,'출결유형'!$L:$M,2,0),"") -> 5 | E9: 지각 | G9: ="INSERT INTO tblAttendanceScore VALUES (" & A9 & ", " & B9 & ", " & C9 & ", " & D9 & ");" -> INSERT INTO tblAttendanceScore VALUES (seqAttendanceScore.nextval, -0.25, 8, 5);
A10: seqAttendanceScore.nextval | B10: =iferror(VLOOKUP(E10,'출결유형'!$A:$C,2,0),"") -> 0 | C10: 9 | D10: =iferror(VLOOKUP(E10,'출결유형'!$L:$M,2,0),"") -> 1 | E10: 출석 | G10: ="INSERT INTO tblAttendanceScore VALUES (" & A10 & ", " & B10 & ", " & C10 & ", " & D10 & ");" -> INSERT INTO tblAttendanceScore VALUES (seqAttendanceScore.nextval, 0, 9, 1);
A11: seqAttendanceScore.nextval | B11: =iferror(VLOOKUP(E11,'출결유형'!$A:$C,2,0),"") -> 0 | C11: 10 | D11: =iferror(VLOOKUP(E11,'출결유형'!$L:$M,2,0),"") -> 1 | E11: 출석 | G11: ="INSERT INTO tblAttendanceScore VALUES (" & A11 & ", " & B11 & ", " & C11 & ", " & D11 & ");" -> INSERT INTO tblAttendanceScore VALUES (seqAttendanceScore.nextval, 0, 10, 1);
A12: seqAttendanceScore.nextval | B12: =iferror(VLOOKUP(E12,'출결유형'!$A:$C,2,0),"") -> -0.25 | C12: 11 | D12: =iferror(VLOOKUP(E12,'출결유형'!$L:$M,2,0),"") -> 5 | E12: 지각 | G12: ="INSERT INTO tblAttendanceScore VALUES (" & A12 & ", " & B12 & ", " & C12 & ", " & D12 & ");" -> INSERT INTO tblAttendanceScore VALUES (seqAttendanceScore.nextval, -0.25, 11, 5);
A13: seqAttendanceScore.nextval | B13: =iferror(VLOOKUP(E13,'출결유형'!$A:$C,2,0),"") -> -0.25 | C13: 12 | D13: =iferror(VLOOKUP(E13,'출결유형'!$L:$M,2,0),"") -> 5 | E13: 지각 | G13: ="INSERT INTO tblAttendanceScore VALUES (" & A13 & ", " & B13 & ", " & C13 & ", " & D13 & ");" -> INSERT INTO tblAttendanceScore VALUES (seqAttendanceScore.nextval, -0.25, 12, 5);
... A841: seqAttendanceScore.nextval | B841: =iferror(VLOOKUP(E841,'출결유형'!$A:$C,2,0),"") -> 0 | C841: 840 | D841: =iferror(VLOOKUP(E841,'출결유형'!$L:$M,2,0),"") -> 1 | E841: 출석 | G841: ="INSERT INTO tblAttendanceScore VALUES (" & A841 & ", " & B841 & ", " & C841 & ", " & D841 & ");" -> INSERT INTO tblAttendanceScore VALUES (seqAttendanceScore.nextval, 0, 840, 1);

Sheet 출결일지
A1: 출결일지번호 | B1: 교육생번호 | C1: 수업날짜 | D1: 입실시간 | E1: 퇴실시간 | F1: 출결상태
A2: seqDayAttendanceLog.nextval | B2: 1 | C2: 45870 | D2: 45870.38 | E2: 45870.745 | F2: 지각 | H2: ="INSERT INTO tblDayAttendanceLog VALUES (" & A2 & ", " & B2 & ", " & "TO_DATE('" & TEXT(C2, "yyyy-mm-dd") & "', 'YYYY-MM-DD'), " & IF(D2="", "NULL", "TO_DATE('" & TEXT(C2, "yyyy-mm-dd") & " " & TEXT(D2, "hh:mm:ss") & "', 'YYYY-MM-DD HH24:MI:SS')") & ", " & IF(E2="", "NULL", "TO_DATE('" & TEXT(C2, "yyyy-mm-dd") & " " & TEXT(E2, "hh:mm:ss") & "', 'YYYY-MM-DD HH24:MI:SS')") & ");" -> INSERT INTO tblDayAttendanceLog VALUES (seqDayAttendanceLog.nextval, 1, TO_DATE('2025-08-01', 'YYYY-MM-DD'), TO_DATE('2025-08-01 09:07:00', 'YYYY-MM-DD HH24:MI:SS'), TO_DATE('2025-08-01 17:53:00', 'YYYY-MM-DD HH24:MI:SS'));
A3: seqDayAttendanceLog.nextval | B3: 2 | C3: 45870 | D3: 45870.351 | E3: 45870.747 | F3: 출석 | H3: ="INSERT INTO tblDayAttendanceLog VALUES (" & A3 & ", " & B3 & ", " & "TO_DATE('" & TEXT(C3, "yyyy-mm-dd") & "', 'YYYY-MM-DD'), " & IF(D3="", "NULL", "TO_DATE('" & TEXT(C3, "yyyy-mm-dd") & " " & TEXT(D3, "hh:mm:ss") & "', 'YYYY-MM-DD HH24:MI:SS')") & ", " & IF(E3="", "NULL", "TO_DATE('" & TEXT(C3, "yyyy-mm-dd") & " " & TEXT(E3, "hh:mm:ss") & "', 'YYYY-MM-DD HH24:MI:SS')") & ");" -> INSERT INTO tblDayAttendanceLog VALUES (seqDayAttendanceLog.nextval, 2, TO_DATE('2025-08-01', 'YYYY-MM-DD'), TO_DATE('2025-08-01 08:26:00', 'YYYY-MM-DD HH24:MI:SS'), TO_DATE('2025-08-01 17:55:00', 'YYYY-MM-DD HH24:MI:SS'));
A4: seqDayAttendanceLog.nextval | B4: 3 | C4: 45870 | D4: 45870.384 | E4: 45870.749 | F4: 지각 | H4: ="INSERT INTO tblDayAttendanceLog VALUES (" & A4 & ", " & B4 & ", " & "TO_DATE('" & TEXT(C4, "yyyy-mm-dd") & "', 'YYYY-MM-DD'), " & IF(D4="", "NULL", "TO_DATE('" & TEXT(C4, "yyyy-mm-dd") & " " & TEXT(D4, "hh:mm:ss") & "', 'YYYY-MM-DD HH24:MI:SS')") & ", " & IF(E4="", "NULL", "TO_DATE('" & TEXT(C4, "yyyy-mm-dd") & " " & TEXT(E4, "hh:mm:ss") & "', 'YYYY-MM-DD HH24:MI:SS')") & ");" -> INSERT INTO tblDayAttendanceLog VALUES (seqDayAttendanceLog.nextval, 3, TO_DATE('2025-08-01', 'YYYY-MM-DD'), TO_DATE('2025-08-01 09:13:00', 'YYYY-MM-DD HH24:MI:SS'), TO_DATE('2025-08-01 17:58:00', 'YYYY-MM-DD HH24:MI:SS'));
A5: seqDayAttendanceLog.nextval | B5: 4 | C5: 45870 | D5: 45870.335 | E5: 45870.745 | F5: 출석 | H5: ="INSERT INTO tblDayAttendanceLog VALUES (" & A5 & ", " & B5 & ", " & "TO_DATE('" & TEXT(C5, "yyyy-mm-dd") & "', 'YYYY-MM-DD'), " & IF(D5="", "NULL", "TO_DATE('" & TEXT(C5, "yyyy-mm-dd") & " " & TEXT(D5, "hh:mm:ss") & "', 'YYYY-MM-DD HH24:MI:SS')") & ", " & IF(E5="", "NULL", "TO_DATE('" & TEXT(C5, "yyyy-mm-dd") & " " & TEXT(E5, "hh:mm:ss") & "', 'YYYY-MM-DD HH24:MI:SS')") & ");" -> INSERT INTO tblDayAttendanceLog VALUES (seqDayAttendanceLog.nextval, 4, TO_DATE('2025-08-01', 'YYYY-MM-DD'), TO_DATE('2025-08-01 08:02:00', 'YYYY-MM-DD HH24:MI:SS'), TO_DATE('2025-08-01 17:53:00', 'YYYY-MM-DD HH24:MI:SS'));
A6: seqDayAttendanceLog.nextval | B6: 5 | C6: 45870 | D6: 45870.37 | E6: 45870.744 | F6: 출석 | H6: ="INSERT INTO tblDayAttendanceLog VALUES (" & A6 & ", " & B6 & ", " & "TO_DATE('" & TEXT(C6, "yyyy-mm-dd") & "', 'YYYY-MM-DD'), " & IF(D6="", "NULL", "TO_DATE('" & TEXT(C6, "yyyy-mm-dd") & " " & TEXT(D6, "hh:mm:ss") & "', 'YYYY-MM-DD HH24:MI:SS')") & ", " & IF(E6="", "NULL", "TO_DATE('" & TEXT(C6, "yyyy-mm-dd") & " " & TEXT(E6, "hh:mm:ss") & "', 'YYYY-MM-DD HH24:MI:SS')") & ");" -> INSERT INTO tblDayAttendanceLog VALUES (seqDayAttendanceLog.nextval, 5, TO_DATE('2025-08-01', 'YYYY-MM-DD'), TO_DATE('2025-08-01 08:53:00', 'YYYY-MM-DD HH24:MI:SS'), TO_DATE('2025-08-01 17:52:00', 'YYYY-MM-DD HH24:MI:SS'));
A7: seqDayAttendanceLog.nextval | B7: 6 | C7: 45870 | D7: 45870.358 | E7: 45870.748 | F7: 출석 | H7: ="INSERT INTO tblDayAttendanceLog VALUES (" & A7 & ", " & B7 & ", " & "TO_DATE('" & TEXT(C7, "yyyy-mm-dd") & "', 'YYYY-MM-DD'), " & IF(D7="", "NULL", "TO_DATE('" & TEXT(C7, "yyyy-mm-dd") & " " & TEXT(D7, "hh:mm:ss") & "', 'YYYY-MM-DD HH24:MI:SS')") & ", " & IF(E7="", "NULL", "TO_DATE('" & TEXT(C7, "yyyy-mm-dd") & " " & TEXT(E7, "hh:mm:ss") & "', 'YYYY-MM-DD HH24:MI:SS')") & ");" -> INSERT INTO tblDayAttendanceLog VALUES (seqDayAttendanceLog.nextval, 6, TO_DATE('2025-08-01', 'YYYY-MM-DD'), TO_DATE('2025-08-01 08:35:00', 'YYYY-MM-DD HH24:MI:SS'), TO_DATE('2025-08-01 17:57:00', 'YYYY-MM-DD HH24:MI:SS'));
A8: seqDayAttendanceLog.nextval | B8: 7 | C8: 45870 | D8: 45870.364 | E8: 45870.744 | F8: 출석 | H8: ="INSERT INTO tblDayAttendanceLog VALUES (" & A8 & ", " & B8 & ", " & "TO_DATE('" & TEXT(C8, "yyyy-mm-dd") & "', 'YYYY-MM-DD'), " & IF(D8="", "NULL", "TO_DATE('" & TEXT(C8, "yyyy-mm-dd") & " " & TEXT(D8, "hh:mm:ss") & "', 'YYYY-MM-DD HH24:MI:SS')") & ", " & IF(E8="", "NULL", "TO_DATE('" & TEXT(C8, "yyyy-mm-dd") & " " & TEXT(E8, "hh:mm:ss") & "', 'YYYY-MM-DD HH24:MI:SS')") & ");" -> INSERT INTO tblDayAttendanceLog VALUES (seqDayAttendanceLog.nextval, 7, TO_DATE('2025-08-01', 'YYYY-MM-DD'), TO_DATE('2025-08-01 08:44:00', 'YYYY-MM-DD HH24:MI:SS'), TO_DATE('2025-08-01 17:51:00', 'YYYY-MM-DD HH24:MI:SS'));
A9: seqDayAttendanceLog.nextval | B9: 8 | C9: 45870 | D9: 45870.375 | E9: 45870.745 | F9: 지각 | H9: ="INSERT INTO tblDayAttendanceLog VALUES (" & A9 & ", " & B9 & ", " & "TO_DATE('" & TEXT(C9, "yyyy-mm-dd") & "', 'YYYY-MM-DD'), " & IF(D9="", "NULL", "TO_DATE('" & TEXT(C9, "yyyy-mm-dd") & " " & TEXT(D9, "hh:mm:ss") & "', 'YYYY-MM-DD HH24:MI:SS')") & ", " & IF(E9="", "NULL", "TO_DATE('" & TEXT(C9, "yyyy-mm-dd") & " " & TEXT(E9, "hh:mm:ss") & "', 'YYYY-MM-DD HH24:MI:SS')") & ");" -> INSERT INTO tblDayAttendanceLog VALUES (seqDayAttendanceLog.nextval, 8, TO_DATE('2025-08-01', 'YYYY-MM-DD'), TO_DATE('2025-08-01 09:00:00', 'YYYY-MM-DD HH24:MI:SS'), TO_DATE('2025-08-01 17:53:00', 'YYYY-MM-DD HH24:MI:SS'));
A10: seqDayAttendanceLog.nextval | B10: 9 | C10: 45870 | D10: 45870.365 | E10: 45870.748 | F10: 출석 | H10: ="INSERT INTO tblDayAttendanceLog VALUES (" & A10 & ", " & B10 & ", " & "TO_DATE('" & TEXT(C10, "yyyy-mm-dd") & "', 'YYYY-MM-DD'), " & IF(D10="", "NULL", "TO_DATE('" & TEXT(C10, "yyyy-mm-dd") & " " & TEXT(D10, "hh:mm:ss") & "', 'YYYY-MM-DD HH24:MI:SS')") & ", " & IF(E10="", "NULL", "TO_DATE('" & TEXT(C10, "yyyy-mm-dd") & " " & TEXT(E10, "hh:mm:ss") & "', 'YYYY-MM-DD HH24:MI:SS')") & ");" -> INSERT INTO tblDayAttendanceLog VALUES (seqDayAttendanceLog.nextval, 9, TO_DATE('2025-08-01', 'YYYY-MM-DD'), TO_DATE('2025-08-01 08:45:00', 'YYYY-MM-DD HH24:MI:SS'), TO_DATE('2025-08-01 17:57:00', 'YYYY-MM-DD HH24:MI:SS'));
A11: seqDayAttendanceLog.nextval | B11: 10 | C11: 45870 | D11: 45870.351 | E11: 45870.747 | F11: 출석 | H11: ="INSERT INTO tblDayAttendanceLog VALUES (" & A11 & ", " & B11 & ", " & "TO_DATE('" & TEXT(C11, "yyyy-mm-dd") & "', 'YYYY-MM-DD'), " & IF(D11="", "NULL", "TO_DATE('" & TEXT(C11, "yyyy-mm-dd") & " " & TEXT(D11, "hh:mm:ss") & "', 'YYYY-MM-DD HH24:MI:SS')") & ", " & IF(E11="", "NULL", "TO_DATE('" & TEXT(C11, "yyyy-mm-dd") & " " & TEXT(E11, "hh:mm:ss") & "', 'YYYY-MM-DD HH24:MI:SS')") & ");" -> INSERT INTO tblDayAttendanceLog VALUES (seqDayAttendanceLog.nextval, 10, TO_DATE('2025-08-01', 'YYYY-MM-DD'), TO_DATE('2025-08-01 08:26:00', 'YYYY-MM-DD HH24:MI:SS'), TO_DATE('2025-08-01 17:56:00', 'YYYY-MM-DD HH24:MI:SS'));
A12: seqDayAttendanceLog.nextval | B12: 11 | C12: 45870 | D12: 45870.403 | E12: 45870.749 | F12: 지각 | H12: ="INSERT INTO tblDayAttendanceLog VALUES (" & A12 & ", " & B12 & ", " & "TO_DATE('" & TEXT(C12, "yyyy-mm-dd") & "', 'YYYY-MM-DD'), " & IF(D12="", "NULL", "TO_DATE('" & TEXT(C12, "yyyy-mm-dd") & " " & TEXT(D12, "hh:mm:ss") & "', 'YYYY-MM-DD HH24:MI:SS')") & ", " & IF(E12="", "NULL", "TO_DATE('" & TEXT(C12, "yyyy-mm-dd") & " " & TEXT(E12, "hh:mm:ss") & "', 'YYYY-MM-DD HH24:MI:SS')") & ");" -> INSERT INTO tblDayAttendanceLog VALUES (seqDayAttendanceLog.nextval, 11, TO_DATE('2025-08-01', 'YYYY-MM-DD'), TO_DATE('2025-08-01 09:41:00', 'YYYY-MM-DD HH24:MI:SS'), TO_DATE('2025-08-01 17:58:00', 'YYYY-MM-DD HH24:MI:SS'));
A13: seqDayAttendanceLog.nextval | B13: 12 | C13: 45870 | D13: 45870.401 | E13: 45870.743 | F13: 지각 | H13: ="INSERT INTO tblDayAttendanceLog VALUES (" & A13 & ", " & B13 & ", " & "TO_DATE('" & TEXT(C13, "yyyy-mm-dd") & "', 'YYYY-MM-DD'), " & IF(D13="", "NULL", "TO_DATE('" & TEXT(C13, "yyyy-mm-dd") & " " & TEXT(D13, "hh:mm:ss") & "', 'YYYY-MM-DD HH24:MI:SS')") & ", " & IF(E13="", "NULL", "TO_DATE('" & TEXT(C13, "yyyy-mm-dd") & " " & TEXT(E13, "hh:mm:ss") & "', 'YYYY-MM-DD HH24:MI:SS')") & ");" -> INSERT INTO tblDayAttendanceLog VALUES (seqDayAttendanceLog.nextval, 12, TO_DATE('2025-08-01', 'YYYY-MM-DD'), TO_DATE('2025-08-01 09:37:00', 'YYYY-MM-DD HH24:MI:SS'), TO_DATE('2025-08-01 17:50:00', 'YYYY-MM-DD HH24:MI:SS'));
... A90: seqDayAttendanceLog.nextval | B90: 89 | C90: 45870 | D90: 45870.408 | E90: 45870.744 | F90: 지각 | H90: ="INSERT INTO tblDayAttendanceLog VALUES (" & A90 & ", " & B90 & ", " & "TO_DATE('" & TEXT(C90, "yyyy-mm-dd") & "', 'YYYY-MM-DD'), " & IF(D90="", "NULL", "TO_DATE('" & TEXT(C90, "yyyy-mm-dd") & " " & TEXT(D90, "hh:mm:ss") & "', 'YYYY-MM-DD HH24:MI:SS')") & ", " & IF(E90="", "NULL", "TO_DATE('" & TEXT(C90, "yyyy-mm-dd") & " " & TEXT(E90, "hh:mm:ss") & "', 'YYYY-MM-DD HH24:MI:SS')") & ");" -> INSERT INTO tblDayAttendanceLog VALUES (seqDayAttendanceLog.nextval, 89, TO_DATE('2025-08-01', 'YYYY-MM-DD'), TO_DATE('2025-08-01 09:47:00', 'YYYY-MM-DD HH24:MI:SS'), TO_DATE('2025-08-01 17:51:00', 'YYYY-MM-DD HH24:MI:SS'));
A91: seqDayAttendanceLog.nextval | B91: 90 | C91: 45870 | F91: 결석 | H91: ="INSERT INTO tblDayAttendanceLog VALUES (" & A91 & ", " & B91 & ", " & "TO_DATE('" & TEXT(C91, "yyyy-mm-dd") & "', 'YYYY-MM-DD'), " & IF(D91="", "NULL", "TO_DATE('" & TEXT(C91, "yyyy-mm-dd") & " " & TEXT(D91, "hh:mm:ss") & "', 'YYYY-MM-DD HH24:MI:SS')") & ", " & IF(E91="", "NULL", "TO_DATE('" & TEXT(C91, "yyyy-mm-dd") & " " & TEXT(E91, "hh:mm:ss") & "', 'YYYY-MM-DD HH24:MI:SS')") & ");" -> INSERT INTO tblDayAttendanceLog VALUES (seqDayAttendanceLog.nextval, 90, TO_DATE('2025-08-01', 'YYYY-MM-DD'), NULL, NULL);
A92: seqDayAttendanceLog.nextval | B92: 91 | C92: 45870 | F92: 결석 | H92: ="INSERT INTO tblDayAttendanceLog VALUES (" & A92 & ", " & B92 & ", " & "TO_DATE('" & TEXT(C92, "yyyy-mm-dd") & "', 'YYYY-MM-DD'), " & IF(D92="", "NULL", "TO_DATE('" & TEXT(C92, "yyyy-mm-dd") & " " & TEXT(D92, "hh:mm:ss") & "', 'YYYY-MM-DD HH24:MI:SS')") & ", " & IF(E92="", "NULL", "TO_DATE('" & TEXT(C92, "yyyy-mm-dd") & " " & TEXT(E92, "hh:mm:ss") & "', 'YYYY-MM-DD HH24:MI:SS')") & ");" -> INSERT INTO tblDayAttendanceLog VALUES (seqDayAttendanceLog.nextval, 91, TO_DATE('2025-08-01', 'YYYY-MM-DD'), NULL, NULL);
A93: seqDayAttendanceLog.nextval | B93: 92 | C93: 45870 | D93: 45870.375 | E93: 45870.745 | F93: 지각 | H93: ="INSERT INTO tblDayAttendanceLog VALUES (" & A93 & ", " & B93 & ", " & "TO_DATE('" & TEXT(C93, "yyyy-mm-dd") & "', 'YYYY-MM-DD'), " & IF(D93="", "NULL", "TO_DATE('" & TEXT(C93, "yyyy-mm-dd") & " " & TEXT(D93, "hh:mm:ss") & "', 'YYYY-MM-DD HH24:MI:SS')") & ", " & IF(E93="", "NULL", "TO_DATE('" & TEXT(C93, "yyyy-mm-dd") & " " & TEXT(E93, "hh:mm:ss") & "', 'YYYY-MM-DD HH24:MI:SS')") & ");" -> INSERT INTO tblDayAttendanceLog VALUES (seqDayAttendanceLog.nextval, 92, TO_DATE('2025-08-01', 'YYYY-MM-DD'), TO_DATE('2025-08-01 09:00:00', 'YYYY-MM-DD HH24:MI:SS'), TO_DATE('2025-08-01 17:53:00', 'YYYY-MM-DD HH24:MI:SS'));
A94: seqDayAttendanceLog.nextval | B94: 93 | C94: 45870 | D94: 45870.391 | E94: 45870.748 | F94: 지각 | H94: ="INSERT INTO tblDayAttendanceLog VALUES (" & A94 & ", " & B94 & ", " & "TO_DATE('" & TEXT(C94, "yyyy-mm-dd") & "', 'YYYY-MM-DD'), " & IF(D94="", "NULL", "TO_DATE('" & TEXT(C94, "yyyy-mm-dd") & " " & TEXT(D94, "hh:mm:ss") & "', 'YYYY-MM-DD HH24:MI:SS')") & ", " & IF(E94="", "NULL", "TO_DATE('" & TEXT(C94, "yyyy-mm-dd") & " " & TEXT(E94, "hh:mm:ss") & "', 'YYYY-MM-DD HH24:MI:SS')") & ");" -> INSERT INTO tblDayAttendanceLog VALUES (seqDayAttendanceLog.nextval, 93, TO_DATE('2025-08-01', 'YYYY-MM-DD'), TO_DATE('2025-08-01 09:23:00', 'YYYY-MM-DD HH24:MI:SS'), TO_DATE('2025-08-01 17:57:00', 'YYYY-MM-DD HH24:MI:SS'));
A95: seqDayAttendanceLog.nextval | B95: 94 | C95: 45870 | D95: 45870.349 | E95: 45870.744 | F95: 출석 | H95: ="INSERT INTO tblDayAttendanceLog VALUES (" & A95 & ", " & B95 & ", " & "TO_DATE('" & TEXT(C95, "yyyy-mm-dd") & "', 'YYYY-MM-DD'), " & IF(D95="", "NULL", "TO_DATE('" & TEXT(C95, "yyyy-mm-dd") & " " & TEXT(D95, "hh:mm:ss") & "', 'YYYY-MM-DD HH24:MI:SS')") & ", " & IF(E95="", "NULL", "TO_DATE('" & TEXT(C95, "yyyy-mm-dd") & " " & TEXT(E95, "hh:mm:ss") & "', 'YYYY-MM-DD HH24:MI:SS')") & ");" -> INSERT INTO tblDayAttendanceLog VALUES (seqDayAttendanceLog.nextval, 94, TO_DATE('2025-08-01', 'YYYY-MM-DD'), TO_DATE('2025-08-01 08:22:00', 'YYYY-MM-DD HH24:MI:SS'), TO_DATE('2025-08-01 17:52:00', 'YYYY-MM-DD HH24:MI:SS'));
A96: seqDayAttendanceLog.nextval | B96: 95 | C96: 45870 | D96: 45870.387 | E96: 45870.746 | F96: 지각 | H96: ="INSERT INTO tblDayAttendanceLog VALUES (" & A96 & ", " & B96 & ", " & "TO_DATE('" & TEXT(C96, "yyyy-mm-dd") & "', 'YYYY-MM-DD'), " & IF(D96="", "NULL", "TO_DATE('" & TEXT(C96, "yyyy-mm-dd") & " " & TEXT(D96, "hh:mm:ss") & "', 'YYYY-MM-DD HH24:MI:SS')") & ", " & IF(E96="", "NULL", "TO_DATE('" & TEXT(C96, "yyyy-mm-dd") & " " & TEXT(E96, "hh:mm:ss") & "', 'YYYY-MM-DD HH24:MI:SS')") & ");" -> INSERT INTO tblDayAttendanceLog VALUES (seqDayAttendanceLog.nextval, 95, TO_DATE('2025-08-01', 'YYYY-MM-DD'), TO_DATE('2025-08-01 09:18:00', 'YYYY-MM-DD HH24:MI:SS'), TO_DATE('2025-08-01 17:54:00', 'YYYY-MM-DD HH24:MI:SS'));
A97: seqDayAttendanceLog.nextval | B97: 96 | C97: 45870 | D97: 45870.367 | E97: 45870.58 | F97: 조퇴 | H97: ="INSERT INTO tblDayAttendanceLog VALUES (" & A97 & ", " & B97 & ", " & "TO_DATE('" & TEXT(C97, "yyyy-mm-dd") & "', 'YYYY-MM-DD'), " & IF(D97="", "NULL", "TO_DATE('" & TEXT(C97, "yyyy-mm-dd") & " " & TEXT(D97, "hh:mm:ss") & "', 'YYYY-MM-DD HH24:MI:SS')") & ", " & IF(E97="", "NULL", "TO_DATE('" & TEXT(C97, "yyyy-mm-dd") & " " & TEXT(E97, "hh:mm:ss") & "', 'YYYY-MM-DD HH24:MI:SS')") & ");" -> INSERT INTO tblDayAttendanceLog VALUES (seqDayAttendanceLog.nextval, 96, TO_DATE('2025-08-01', 'YYYY-MM-DD'), TO_DATE('2025-08-01 08:48:00', 'YYYY-MM-DD HH24:MI:SS'), TO_DATE('2025-08-01 13:55:00', 'YYYY-MM-DD HH24:MI:SS'));
A98: seqDayAttendanceLog.nextval | B98: 97 | C98: 45870 | D98: 45870.365 | E98: 45870.744 | F98: 출석 | H98: ="INSERT INTO tblDayAttendanceLog VALUES (" & A98 & ", " & B98 & ", " & "TO_DATE('" & TEXT(C98, "yyyy-mm-dd") & "', 'YYYY-MM-DD'), " & IF(D98="", "NULL", "TO_DATE('" & TEXT(C98, "yyyy-mm-dd") & " " & TEXT(D98, "hh:mm:ss") & "', 'YYYY-MM-DD HH24:MI:SS')") & ", " & IF(E98="", "NULL", "TO_DATE('" & TEXT(C98, "yyyy-mm-dd") & " " & TEXT(E98, "hh:mm:ss") & "', 'YYYY-MM-DD HH24:MI:SS')") & ");" -> INSERT INTO tblDayAttendanceLog VALUES (seqDayAttendanceLog.nextval, 97, TO_DATE('2025-08-01', 'YYYY-MM-DD'), TO_DATE('2025-08-01 08:45:00', 'YYYY-MM-DD HH24:MI:SS'), TO_DATE('2025-08-01 17:51:00', 'YYYY-MM-DD HH24:MI:SS'));
A99: seqDayAttendanceLog.nextval | B99: 98 | C99: 45870 | D99: 45870.348 | E99: 45870.743 | F99: 출석 | H99: ="INSERT INTO tblDayAttendanceLog VALUES (" & A99 & ", " & B99 & ", " & "TO_DATE('" & TEXT(C99, "yyyy-mm-dd") & "', 'YYYY-MM-DD'), " & IF(D99="", "NULL", "TO_DATE('" & TEXT(C99, "yyyy-mm-dd") & " " & TEXT(D99, "hh:mm:ss") & "', 'YYYY-MM-DD HH24:MI:SS')") & ", " & IF(E99="", "NULL", "TO_DATE('" & TEXT(C99, "yyyy-mm-dd") & " " & TEXT(E99, "hh:mm:ss") & "', 'YYYY-MM-DD HH24:MI:SS')") & ");" -> INSERT INTO tblDayAttendanceLog VALUES (seqDayAttendanceLog.nextval, 98, TO_DATE('2025-08-01', 'YYYY-MM-DD'), TO_DATE('2025-08-01 08:21:00', 'YYYY-MM-DD HH24:MI:SS'), TO_DATE('2025-08-01 17:50:00', 'YYYY-MM-DD HH24:MI:SS'));
A100: seqDayAttendanceLog.nextval | B100: 99 | C100: 45870 | D100: 45870.401 | E100: 45870.745 | F100: 지각 | H100: ="INSERT INTO tblDayAttendanceLog VALUES (" & A100 & ", " & B100 & ", " & "TO_DATE('" & TEXT(C100, "yyyy-mm-dd") & "', 'YYYY-MM-DD'), " & IF(D100="", "NULL", "TO_DATE('" & TEXT(C100, "yyyy-mm-dd") & " " & TEXT(D100, "hh:mm:ss") & "', 'YYYY-MM-DD HH24:MI:SS')") & ", " & IF(E100="", "NULL", "TO_DATE('" & TEXT(C100, "yyyy-mm-dd") & " " & TEXT(E100, "hh:mm:ss") & "', 'YYYY-MM-DD HH24:MI:SS')") & ");" -> INSERT INTO tblDayAttendanceLog VALUES (seqDayAttendanceLog.nextval, 99, TO_DATE('2025-08-01', 'YYYY-MM-DD'), TO_DATE('2025-08-01 09:37:00', 'YYYY-MM-DD HH24:MI:SS'), TO_DATE('2025-08-01 17:53:00', 'YYYY-MM-DD HH24:MI:SS'));
A101: seqDayAttendanceLog.nextval | B101: 100 | C101: 45870 | D101: 45870.344 | E101: 45870.748 | F101: 출석 | H101: ="INSERT INTO tblDayAttendanceLog VALUES (" & A101 & ", " & B101 & ", " & "TO_DATE('" & TEXT(C101, "yyyy-mm-dd") & "', 'YYYY-MM-DD'), " & IF(D101="", "NULL", "TO_DATE('" & TEXT(C101, "yyyy-mm-dd") & " " & TEXT(D101, "hh:mm:ss") & "', 'YYYY-MM-DD HH24:MI:SS')") & ", " & IF(E101="", "NULL", "TO_DATE('" & TEXT(C101, "yyyy-mm-dd") & " " & TEXT(E101, "hh:mm:ss") & "', 'YYYY-MM-DD HH24:MI:SS')") & ");" -> INSERT INTO tblDayAttendanceLog VALUES (seqDayAttendanceLog.nextval, 100, TO_DATE('2025-08-01', 'YYYY-MM-DD'), TO_DATE('2025-08-01 08:15:00', 'YYYY-MM-DD HH24:MI:SS'), TO_DATE('2025-08-01 17:57:00', 'YYYY-MM-DD HH24:MI:SS'));
A102: seqDayAttendanceLog.nextval | B102: 101 | C102: 45870 | D102: 45870.352 | E102: 45870.748 | F102: 출석 | H102: ="INSERT INTO tblDayAttendanceLog VALUES (" & A102 & ", " & B102 & ", " & "TO_DATE('" & TEXT(C102, "yyyy-mm-dd") & "', 'YYYY-MM-DD'), " & IF(D102="", "NULL", "TO_DATE('" & TEXT(C102, "yyyy-mm-dd") & " " & TEXT(D102, "hh:mm:ss") & "', 'YYYY-MM-DD HH24:MI:SS')") & ", " & IF(E102="", "NULL", "TO_DATE('" & TEXT(C102, "yyyy-mm-dd") & " " & TEXT(E102, "hh:mm:ss") & "', 'YYYY-MM-DD HH24:MI:SS')") & ");" -> INSERT INTO tblDayAttendanceLog VALUES (seqDayAttendanceLog.nextval, 101, TO_DATE('2025-08-01', 'YYYY-MM-DD'), TO_DATE('2025-08-01 08:27:00', 'YYYY-MM-DD HH24:MI:SS'), TO_DATE('2025-08-01 17:57:00', 'YYYY-MM-DD HH24:MI:SS'));
A103: seqDayAttendanceLog.nextval | B103: 102 | C103: 45870 | D103: 45870.376 | E103: 45870.745 | F103: 지각 | H103: ="INSERT INTO tblDayAttendanceLog VALUES (" & A103 & ", " & B103 & ", " & "TO_DATE('" & TEXT(C103, "yyyy-mm-dd") & "', 'YYYY-MM-DD'), " & IF(D103="", "NULL", "TO_DATE('" & TEXT(C103, "yyyy-mm-dd") & " " & TEXT(D103, "hh:mm:ss") & "', 'YYYY-MM-DD HH24:MI:SS')") & ", " & IF(E103="", "NULL", "TO_DATE('" & TEXT(C103, "yyyy-mm-dd") & " " & TEXT(E103, "hh:mm:ss") & "', 'YYYY-MM-DD HH24:MI:SS')") & ");" -> INSERT INTO tblDayAttendanceLog VALUES (seqDayAttendanceLog.nextval, 102, TO_DATE('2025-08-01', 'YYYY-MM-DD'), TO_DATE('2025-08-01 09:01:00', 'YYYY-MM-DD HH24:MI:SS'), TO_DATE('2025-08-01 17:53:00', 'YYYY-MM-DD HH24:MI:SS'));
A104: seqDayAttendanceLog.nextval | B104: 103 | C104: 45870 | D104: 45870.345 | E104: 45870.746 | F104: 출석 | H104: ="INSERT INTO tblDayAttendanceLog VALUES (" & A104 & ", " & B104 & ", " & "TO_DATE('" & TEXT(C104, "yyyy-mm-dd") & "', 'YYYY-MM-DD'), " & IF(D104="", "NULL", "TO_DATE('" & TEXT(C104, "yyyy-mm-dd") & " " & TEXT(D104, "hh:mm:ss") & "', 'YYYY-MM-DD HH24:MI:SS')") & ", " & IF(E104="", "NULL", "TO_DATE('" & TEXT(C104, "yyyy-mm-dd") & " " & TEXT(E104, "hh:mm:ss") & "', 'YYYY-MM-DD HH24:MI:SS')") & ");" -> INSERT INTO tblDayAttendanceLog VALUES (seqDayAttendanceLog.nextval, 103, TO_DATE('2025-08-01', 'YYYY-MM-DD'), TO_DATE('2025-08-01 08:17:00', 'YYYY-MM-DD HH24:MI:SS'), TO_DATE('2025-08-01 17:54:00', 'YYYY-MM-DD HH24:MI:SS'));
... A112: seqDayAttendanceLog.nextval | B112: 111 | C112: 45870 | D112: 45870.398 | E112: 45870.747 | F112: 지각 | H112: ="INSERT INTO tblDayAttendanceLog VALUES (" & A112 & ", " & B112 & ", " & "TO_DATE('" & TEXT(C112, "yyyy-mm-dd") & "', 'YYYY-MM-DD'), " & IF(D112="", "NULL", "TO_DATE('" & TEXT(C112, "yyyy-mm-dd") & " " & TEXT(D112, "hh:mm:ss") & "', 'YYYY-MM-DD HH24:MI:SS')") & ", " & IF(E112="", "NULL", "TO_DATE('" & TEXT(C112, "yyyy-mm-dd") & " " & TEXT(E112, "hh:mm:ss") & "', 'YYYY-MM-DD HH24:MI:SS')") & ");" -> INSERT INTO tblDayAttendanceLog VALUES (seqDayAttendanceLog.nextval, 111, TO_DATE('2025-08-01', 'YYYY-MM-DD'), TO_DATE('2025-08-01 09:33:00', 'YYYY-MM-DD HH24:MI:SS'), TO_DATE('2025-08-01 17:56:00', 'YYYY-MM-DD HH24:MI:SS'));
A113: seqDayAttendanceLog.nextval | B113: 112 | C113: 45870 | F113: 결석 | H113: ="INSERT INTO tblDayAttendanceLog VALUES (" & A113 & ", " & B113 & ", " & "TO_DATE('" & TEXT(C113, "yyyy-mm-dd") & "', 'YYYY-MM-DD'), " & IF(D113="", "NULL", "TO_DATE('" & TEXT(C113, "yyyy-mm-dd") & " " & TEXT(D113, "hh:mm:ss") & "', 'YYYY-MM-DD HH24:MI:SS')") & ", " & IF(E113="", "NULL", "TO_DATE('" & TEXT(C113, "yyyy-mm-dd") & " " & TEXT(E113, "hh:mm:ss") & "', 'YYYY-MM-DD HH24:MI:SS')") & ");" -> INSERT INTO tblDayAttendanceLog VALUES (seqDayAttendanceLog.nextval, 112, TO_DATE('2025-08-01', 'YYYY-MM-DD'), NULL, NULL);
A114: seqDayAttendanceLog.nextval | B114: 113 | C114: 45870 | D114: 45870.342 | E114: 45870.744 | F114: 출석 | H114: ="INSERT INTO tblDayAttendanceLog VALUES (" & A114 & ", " & B114 & ", " & "TO_DATE('" & TEXT(C114, "yyyy-mm-dd") & "', 'YYYY-MM-DD'), " & IF(D114="", "NULL", "TO_DATE('" & TEXT(C114, "yyyy-mm-dd") & " " & TEXT(D114, "hh:mm:ss") & "', 'YYYY-MM-DD HH24:MI:SS')") & ", " & IF(E114="", "NULL", "TO_DATE('" & TEXT(C114, "yyyy-mm-dd") & " " & TEXT(E114, "hh:mm:ss") & "', 'YYYY-MM-DD HH24:MI:SS')") & ");" -> INSERT INTO tblDayAttendanceLog VALUES (seqDayAttendanceLog.nextval, 113, TO_DATE('2025-08-01', 'YYYY-MM-DD'), TO_DATE('2025-08-01 08:13:00', 'YYYY-MM-DD HH24:MI:SS'), TO_DATE('2025-08-01 17:51:00', 'YYYY-MM-DD HH24:MI:SS'));
A115: seqDayAttendanceLog.nextval | B115: 114 | C115: 45870 | D115: 45870.406 | E115: 45870.744 | F115: 지각 | H115: ="INSERT INTO tblDayAttendanceLog VALUES (" & A115 & ", " & B115 & ", " & "TO_DATE('" & TEXT(C115, "yyyy-mm-dd") & "', 'YYYY-MM-DD'), " & IF(D115="", "NULL", "TO_DATE('" & TEXT(C115, "yyyy-mm-dd") & " " & TEXT(D115, "hh:mm:ss") & "', 'YYYY-MM-DD HH24:MI:SS')") & ", " & IF(E115="", "NULL", "TO_DATE('" & TEXT(C115, "yyyy-mm-dd") & " " & TEXT(E115, "hh:mm:ss") & "', 'YYYY-MM-DD HH24:MI:SS')") & ");" -> INSERT INTO tblDayAttendanceLog VALUES (seqDayAttendanceLog.nextval, 114, TO_DATE('2025-08-01', 'YYYY-MM-DD'), TO_DATE('2025-08-01 09:45:00', 'YYYY-MM-DD HH24:MI:SS'), TO_DATE('2025-08-01 17:51:00', 'YYYY-MM-DD HH24:MI:SS'));
A116: seqDayAttendanceLog.nextval | B116: 115 | C116: 45870 | D116: 45870.369 | E116: 45870.748 | F116: 출석 | H116: ="INSERT INTO tblDayAttendanceLog VALUES (" & A116 & ", " & B116 & ", " & "TO_DATE('" & TEXT(C116, "yyyy-mm-dd") & "', 'YYYY-MM-DD'), " & IF(D116="", "NULL", "TO_DATE('" & TEXT(C116, "yyyy-mm-dd") & " " & TEXT(D116, "hh:mm:ss") & "', 'YYYY-MM-DD HH24:MI:SS')") & ", " & IF(E116="", "NULL", "TO_DATE('" & TEXT(C116, "yyyy-mm-dd") & " " & TEXT(E116, "hh:mm:ss") & "', 'YYYY-MM-DD HH24:MI:SS')") & ");" -> INSERT INTO tblDayAttendanceLog VALUES (seqDayAttendanceLog.nextval, 115, TO_DATE('2025-08-01', 'YYYY-MM-DD'), TO_DATE('2025-08-01 08:51:00', 'YYYY-MM-DD HH24:MI:SS'), TO_DATE('2025-08-01 17:57:00', 'YYYY-MM-DD HH24:MI:SS'));
A117: seqDayAttendanceLog.nextval | B117: 116 | C117: 45870 | D117: 45870.34 | E117: 45870.745 | F117: 출석 | H117: ="INSERT INTO tblDayAttendanceLog VALUES (" & A117 & ", " & B117 & ", " & "TO_DATE('" & TEXT(C117, "yyyy-mm-dd") & "', 'YYYY-MM-DD'), " & IF(D117="", "NULL", "TO_DATE('" & TEXT(C117, "yyyy-mm-dd") & " " & TEXT(D117, "hh:mm:ss") & "', 'YYYY-MM-DD HH24:MI:SS')") & ", " & IF(E117="", "NULL", "TO_DATE('" & TEXT(C117, "yyyy-mm-dd") & " " & TEXT(E117, "hh:mm:ss") & "', 'YYYY-MM-DD HH24:MI:SS')") & ");" -> INSERT INTO tblDayAttendanceLog VALUES (seqDayAttendanceLog.nextval, 116, TO_DATE('2025-08-01', 'YYYY-MM-DD'), TO_DATE('2025-08-01 08:09:00', 'YYYY-MM-DD HH24:MI:SS'), TO_DATE('2025-08-01 17:53:00', 'YYYY-MM-DD HH24:MI:SS'));
A118: seqDayAttendanceLog.nextval | B118: 117 | C118: 45870 | D118: 45870.341 | E118: 45870.743 | F118: 출석 | H118: ="INSERT INTO tblDayAttendanceLog VALUES (" & A118 & ", " & B118 & ", " & "TO_DATE('" & TEXT(C118, "yyyy-mm-dd") & "', 'YYYY-MM-DD'), " & IF(D118="", "NULL", "TO_DATE('" & TEXT(C118, "yyyy-mm-dd") & " " & TEXT(D118, "hh:mm:ss") & "', 'YYYY-MM-DD HH24:MI:SS')") & ", " & IF(E118="", "NULL", "TO_DATE('" & TEXT(C118, "yyyy-mm-dd") & " " & TEXT(E118, "hh:mm:ss") & "', 'YYYY-MM-DD HH24:MI:SS')") & ");" -> INSERT INTO tblDayAttendanceLog VALUES (seqDayAttendanceLog.nextval, 117, TO_DATE('2025-08-01', 'YYYY-MM-DD'), TO_DATE('2025-08-01 08:11:00', 'YYYY-MM-DD HH24:MI:SS'), TO_DATE('2025-08-01 17:50:00', 'YYYY-MM-DD HH24:MI:SS'));
A119: seqDayAttendanceLog.nextval | B119: 118 | C119: 45870 | D119: 45870.409 | E119: 45870.747 | F119: 지각 | H119: ="INSERT INTO tblDayAttendanceLog VALUES (" & A119 & ", " & B119 & ", " & "TO_DATE('" & TEXT(C119, "yyyy-mm-dd") & "', 'YYYY-MM-DD'), " & IF(D119="", "NULL", "TO_DATE('" & TEXT(C119, "yyyy-mm-dd") & " " & TEXT(D119, "hh:mm:ss") & "', 'YYYY-MM-DD HH24:MI:SS')") & ", " & IF(E119="", "NULL", "TO_DATE('" & TEXT(C119, "yyyy-mm-dd") & " " & TEXT(E119, "hh:mm:ss") & "', 'YYYY-MM-DD HH24:MI:SS')") & ");" -> INSERT INTO tblDayAttendanceLog VALUES (seqDayAttendanceLog.nextval, 118, TO_DATE('2025-08-01', 'YYYY-MM-DD'), TO_DATE('2025-08-01 09:49:00', 'YYYY-MM-DD HH24:MI:SS'), TO_DATE('2025-08-01 17:56:00', 'YYYY-MM-DD HH24:MI:SS'));
A120: seqDayAttendanceLog.nextval | B120: 119 | C120: 45870 | D120: 45870.412 | E120: 45870.748 | F120: 지각 | H120: ="INSERT INTO tblDayAttendanceLog VALUES (" & A120 & ", " & B120 & ", " & "TO_DATE('" & TEXT(C120, "yyyy-mm-dd") & "', 'YYYY-MM-DD'), " & IF(D120="", "NULL", "TO_DATE('" & TEXT(C120, "yyyy-mm-dd") & " " & TEXT(D120, "hh:mm:ss") & "', 'YYYY-MM-DD HH24:MI:SS')") & ", " & IF(E120="", "NULL", "TO_DATE('" & TEXT(C120, "yyyy-mm-dd") & " " & TEXT(E120, "hh:mm:ss") & "', 'YYYY-MM-DD HH24:MI:SS')") & ");" -> INSERT INTO tblDayAttendanceLog VALUES (seqDayAttendanceLog.nextval, 119, TO_DATE('2025-08-01', 'YYYY-MM-DD'), TO_DATE('2025-08-01 09:53:00', 'YYYY-MM-DD HH24:MI:SS'), TO_DATE('2025-08-01 17:57:00', 'YYYY-MM-DD HH24:MI:SS'));
A121: seqDayAttendanceLog.nextval | B121: 120 | C121: 45870 | D121: 45870.406 | E121: 45870.745 | F121: 지각 | H121: ="INSERT INTO tblDayAttendanceLog VALUES (" & A121 & ", " & B121 & ", " & "TO_DATE('" & TEXT(C121, "yyyy-mm-dd") & "', 'YYYY-MM-DD'), " & IF(D121="", "NULL", "TO_DATE('" & TEXT(C121, "yyyy-mm-dd") & " " & TEXT(D121, "hh:mm:ss") & "', 'YYYY-MM-DD HH24:MI:SS')") & ", " & IF(E121="", "NULL", "TO_DATE('" & TEXT(C121, "yyyy-mm-dd") & " " & TEXT(E121, "hh:mm:ss") & "', 'YYYY-MM-DD HH24:MI:SS')") & ");" -> INSERT INTO tblDayAttendanceLog VALUES (seqDayAttendanceLog.nextval, 120, TO_DATE('2025-08-01', 'YYYY-MM-DD'), TO_DATE('2025-08-01 09:45:00', 'YYYY-MM-DD HH24:MI:SS'), TO_DATE('2025-08-01 17:53:00', 'YYYY-MM-DD HH24:MI:SS'));
A122: seqDayAttendanceLog.nextval | B122: 121 | C122: 45870 | D122: 45870.379 | E122: 45870.749 | F122: 지각 | H122: ="INSERT INTO tblDayAttendanceLog VALUES (" & A122 & ", " & B122 & ", " & "TO_DATE('" & TEXT(C122, "yyyy-mm-dd") & "', 'YYYY-MM-DD'), " & IF(D122="", "NULL", "TO_DATE('" & TEXT(C122, "yyyy-mm-dd") & " " & TEXT(D122, "hh:mm:ss") & "', 'YYYY-MM-DD HH24:MI:SS')") & ", " & IF(E122="", "NULL", "TO_DATE('" & TEXT(C122, "yyyy-mm-dd") & " " & TEXT(E122, "hh:mm:ss") & "', 'YYYY-MM-DD HH24:MI:SS')") & ");" -> INSERT INTO tblDayAttendanceLog VALUES (seqDayAttendanceLog.nextval, 121, TO_DATE('2025-08-01', 'YYYY-MM-DD'), TO_DATE('2025-08-01 09:06:00', 'YYYY-MM-DD HH24:MI:SS'), TO_DATE('2025-08-01 17:58:00', 'YYYY-MM-DD HH24:MI:SS'));
A123: seqDayAttendanceLog.nextval | B123: 122 | C123: 45870 | D123: 45870.342 | E123: 45870.743 | F123: 출석 | H123: ="INSERT INTO tblDayAttendanceLog VALUES (" & A123 & ", " & B123 & ", " & "TO_DATE('" & TEXT(C123, "yyyy-mm-dd") & "', 'YYYY-MM-DD'), " & IF(D123="", "NULL", "TO_DATE('" & TEXT(C123, "yyyy-mm-dd") & " " & TEXT(D123, "hh:mm:ss") & "', 'YYYY-MM-DD HH24:MI:SS')") & ", " & IF(E123="", "NULL", "TO_DATE('" & TEXT(C123, "yyyy-mm-dd") & " " & TEXT(E123, "hh:mm:ss") & "', 'YYYY-MM-DD HH24:MI:SS')") & ");" -> INSERT INTO tblDayAttendanceLog VALUES (seqDayAttendanceLog.nextval, 122, TO_DATE('2025-08-01', 'YYYY-MM-DD'), TO_DATE('2025-08-01 08:13:00', 'YYYY-MM-DD HH24:MI:SS'), TO_DATE('2025-08-01 17:50:00', 'YYYY-MM-DD HH24:MI:SS'));
...

Sheet 취업관리
A1: 취업관리번호 | B1: 취업여부 | C1: 고용보험가입날짜 | D1: 수강생번호

Sheet 큐앤에이상담게시판
A1: 게시판번호 | B1: 제목 | C1: 내용 | D1: 등록날짜 | E1: 수강생번호 | F1: 답변번호 | G1: 답변여부번호

Sheet 큐앤에이삭제로그
A1: 삭제번호 | B1: 삭제시간 | C1: 관리자번호 | D1: 게시판번호

Sheet 큐앤에이답변
A1: 답변번호 | B1: 답변내용 | C1: 답변날짜 | D1: 교사번호

Sheet 보상 아이템
A1: 보상번호 | B1: 보상 아이템 목록 | C1: 보상 아이템 가격 | D1: 보상 종류
A2: seqReward.nextval | B2: 애플 정품 유선 이어팟/라이트닝 이어폰 | C2: 55000 | D2: 출결 | F2: ="INSERT INTO 테이블명 VALUES (" & A2 & ", '" & B2 & "', " & C2 & ", '" & D2 & "');" -> INSERT INTO 테이블명 VALUES (seqReward.nextval, '애플 정품 유선 이어팟/라이트닝 이어폰', 55000, '출결');
A3: seqReward.nextval | B3: 삼성 갤럭시 버즈 라이브 (리퍼/특가) | C3: 89000 | D3: 성적 | F3: ="INSERT INTO 테이블명 VALUES (" & A3 & ", '" & B3 & "', " & C3 & ", '" & D3 & "');" -> INSERT INTO 테이블명 VALUES (seqReward.nextval, '삼성 갤럭시 버즈 라이브 (리퍼/특가)', 89000, '성적');
A4: seqReward.nextval | B4: 로지텍 블루투스 무선 마우스 M650 | C4: 54000 | D4: 출결 | F4: ="INSERT INTO 테이블명 VALUES (" & A4 & ", '" & B4 & "', " & C4 & ", '" & D4 & "');" -> INSERT INTO 테이블명 VALUES (seqReward.nextval, '로지텍 블루투스 무선 마우스 M650', 54000, '출결');
A5: seqReward.nextval | B5: 문화상품권 5만원권 | C5: 50000 | D5: 성적 | F5: ="INSERT INTO 테이블명 VALUES (" & A5 & ", '" & B5 & "', " & C5 & ", '" & D5 & "');" -> INSERT INTO 테이블명 VALUES (seqReward.nextval, '문화상품권 5만원권', 50000, '성적');
A6: seqReward.nextval | B6: 신세계 백화점 상품권 10만원권 (이벤트용) | C6: 100000 | D6: 출결 | F6: ="INSERT INTO 테이블명 VALUES (" & A6 & ", '" & B6 & "', " & C6 & ", '" & D6 & "');" -> INSERT INTO 테이블명 VALUES (seqReward.nextval, '신세계 백화점 상품권 10만원권 (이벤트용)', 100000, '출결');
A7: seqReward.nextval | B7: 스타벅스 카드 (잔액형 기프트 카드) | C7: 50000 | D7: 성적 | F7: ="INSERT INTO 테이블명 VALUES (" & A7 & ", '" & B7 & "', " & C7 & ", '" & D7 & "');" -> INSERT INTO 테이블명 VALUES (seqReward.nextval, '스타벅스 카드 (잔액형 기프트 카드)', 50000, '성적');
A8: seqReward.nextval | B8: 무신사 상품권 | C8: 50000 | D8: 성적 | F8: ="INSERT INTO 테이블명 VALUES (" & A8 & ", '" & B8 & "', " & C8 & ", '" & D8 & "');" -> INSERT INTO 테이블명 VALUES (seqReward.nextval, '무신사 상품권', 50000, '성적');
A9: seqReward.nextval | B9: 다이소 프리패스권 (5만원 한도 물품 구매권) | C9: 50000 | D9: 성적 | F9: ="INSERT INTO 테이블명 VALUES (" & A9 & ", '" & B9 & "', " & C9 & ", '" & D9 & "');" -> INSERT INTO 테이블명 VALUES (seqReward.nextval, '다이소 프리패스권 (5만원 한도 물품 구매권)', 50000, '성적');
A10: seqReward.nextval | B10: 스마트 워치 (샤오미/가성비 브랜드) | C10: 65000 | D10: 성적 | F10: ="INSERT INTO 테이블명 VALUES (" & A10 & ", '" & B10 & "', " & C10 & ", '" & D10 & "');" -> INSERT INTO 테이블명 VALUES (seqReward.nextval, '스마트 워치 (샤오미/가성비 브랜드)', 65000, '성적');
A11: seqReward.nextval | B11: 휴대용 보조배터리 (Anker 10000mAh 이상) | C11: 59000 | D11: 출결 | F11: ="INSERT INTO 테이블명 VALUES (" & A11 & ", '" & B11 & "', " & C11 & ", '" & D11 & "');" -> INSERT INTO 테이블명 VALUES (seqReward.nextval, '휴대용 보조배터리 (Anker 10000mAh 이상)', 59000, '출결');
A12: seqReward.nextval | B12: 게이밍 헤드셋 (로지텍 G335 등) | C12: 89000 | D12: 성적 | F12: ="INSERT INTO 테이블명 VALUES (" & A12 & ", '" & B12 & "', " & C12 & ", '" & D12 & "');" -> INSERT INTO 테이블명 VALUES (seqReward.nextval, '게이밍 헤드셋 (로지텍 G335 등)', 89000, '성적');
A13: seqReward.nextval | B13: 책 + 문구류 종합 세트 (학습용 + 굿즈 포함) | C13: 60000 | D13: 출결 | F13: ="INSERT INTO 테이블명 VALUES (" & A13 & ", '" & B13 & "', " & C13 & ", '" & D13 & "');" -> INSERT INTO 테이블명 VALUES (seqReward.nextval, '책 + 문구류 종합 세트 (학습용 + 굿즈 포함)', 60000, '출결');
... A15: seqReward.nextval | B15: 유명 브랜드 텀블러 (스탠리/하이드로플라스크) | C15: 58000 | D15: 성적 | F15: ="INSERT INTO 테이블명 VALUES (" & A15 & ", '" & B15 & "', " & C15 & ", '" & D15 & "');" -> INSERT INTO 테이블명 VALUES (seqReward.nextval, '유명 브랜드 텀블러 (스탠리/하이드로플라스크)', 58000, '성적');

Sheet 관리자
B3: tblAdmin - 관리자 정보
B5: 관리자 번호 | C5: 관리자 이름 | D5: 관리자 주민번호 | E5: 관리자 아이디 | F5: 관리자 비밀번호 | G5: 관리자 월급
B6: seqAdmin.nextval | C6: 김민수 | D6: 871107-2712936 | E6: awMAX973 | F6: rVaWp352 | G6: 4500000 | I6: ="INSERT INTO tblAdmin VALUES (" & B6 & ", '" & C6 & "', '" & D6 & "', '" & E6 & "', '" & F6 & "', " & G6 & ");" -> INSERT INTO tblAdmin VALUES (seqAdmin.nextval, '김민수', '871107-2712936', 'awMAX973', 'rVaWp352', 4500000);
B7: seqAdmin.nextval | C7: 이서연 | D7: 980721-2559672 | E7: WSEpS162 | F7: SglHx256 | G7: 3500000 | I7: ="INSERT INTO tblAdmin VALUES (" & B7 & ", '" & C7 & "', '" & D7 & "', '" & E7 & "', '" & F7 & "', " & G7 & ");" -> INSERT INTO tblAdmin VALUES (seqAdmin.nextval, '이서연', '980721-2559672', 'WSEpS162', 'SglHx256', 3500000);
B8: seqAdmin.nextval | C8: 박지훈 | D8: 930408-1179368 | E8: FpDcQ504 | F8: EKVWW746! | G8: 3700000 | I8: ="INSERT INTO tblAdmin VALUES (" & B8 & ", '" & C8 & "', '" & D8 & "', '" & E8 & "', '" & F8 & "', " & G8 & ");" -> INSERT INTO tblAdmin VALUES (seqAdmin.nextval, '박지훈', '930408-1179368', 'FpDcQ504', 'EKVWW746!', 3700000);
B9: seqAdmin.nextval | C9: 최유진 | D9: 950413-2124882 | E9: YkJgk353 | F9: iciSn755 | G9: 3700000 | I9: ="INSERT INTO tblAdmin VALUES (" & B9 & ", '" & C9 & "', '" & D9 & "', '" & E9 & "', '" & F9 & "', " & G9 & ");" -> INSERT INTO tblAdmin VALUES (seqAdmin.nextval, '최유진', '950413-2124882', 'YkJgk353', 'iciSn755', 3700000);
B10: seqAdmin.nextval | C10: 정우성 | D10: 800326-1595435 | E10: rcegX435 | F10: QrhnT511! | G10: 4000000 | I10: ="INSERT INTO tblAdmin VALUES (" & B10 & ", '" & C10 & "', '" & D10 & "', '" & E10 & "', '" & F10 & "', " & G10 & ");" -> INSERT INTO tblAdmin VALUES (seqAdmin.nextval, '정우성', '800326-1595435', 'rcegX435', 'QrhnT511!', 4000000);

Sheet 취업 관리
A1: 169~382
B3: tblJobPlacement - 취업 관리 (tblStudent 참조)
B5: 취업관리번호 | C5: 수강생 번호 | D5: 취업여부 | E5: 고용보험가입날짜
B6: seqJobPlacement.nextval | C6: 169 | D6: 취업 | E6: =TEXT(RANDBETWEEN(DATE(2023,1,1),DATE(2025,8,4)),"yyyy-mm-dd") -> 2024-01-04 | G6: ="INSERT INTO tblJobPlacement VALUES (" & B6 & ", " & C6 & ", '" & D6 & "', '" & E6 & "');" -> INSERT INTO tblJobPlacement VALUES (seqJobPlacement.nextval, 169, '취업', '2024-01-04');
B7: seqJobPlacement.nextval | C7: 170 | D7: 취업 | E7: =TEXT(RANDBETWEEN(DATE(2023,1,1),DATE(2025,8,4)),"yyyy-mm-dd") -> 2024-02-21 | G7: ="INSERT INTO tblJobPlacement VALUES (" & B7 & ", " & C7 & ", '" & D7 & "', '" & E7 & "');" -> INSERT INTO tblJobPlacement VALUES (seqJobPlacement.nextval, 170, '취업', '2024-02-21');
B8: seqJobPlacement.nextval | C8: 171 | D8: 취업 | E8: =TEXT(RANDBETWEEN(DATE(2023,1,1),DATE(2025,8,4)),"yyyy-mm-dd") -> 2025-03-06 | G8: ="INSERT INTO tblJobPlacement VALUES (" & B8 & ", " & C8 & ", '" & D8 & "', '" & E8 & "');" -> INSERT INTO tblJobPlacement VALUES (seqJobPlacement.nextval, 171, '취업', '2025-03-06');
B9: seqJobPlacement.nextval | C9: 172 | D9: 취업 | E9: =TEXT(RANDBETWEEN(DATE(2023,1,1),DATE(2025,8,4)),"yyyy-mm-dd") -> 2023-09-12 | G9: ="INSERT INTO tblJobPlacement VALUES (" & B9 & ", " & C9 & ", '" & D9 & "', '" & E9 & "');" -> INSERT INTO tblJobPlacement VALUES (seqJobPlacement.nextval, 172, '취업', '2023-09-12');
B10: seqJobPlacement.nextval | C10: 173 | D10: 취업 | E10: =TEXT(RANDBETWEEN(DATE(2023,1,1),DATE(2025,8,4)),"yyyy-mm-dd") -> 2024-05-02 | G10: ="INSERT INTO tblJobPlacement VALUES (" & B10 & ", " & C10 & ", '" & D10 & "', '" & E10 & "');" -> INSERT INTO tblJobPlacement VALUES (seqJobPlacement.nextval, 173, '취업', '2024-05-02');
B11: seqJobPlacement.nextval | C11: 174 | D11: 취업 | E11: =TEXT(RANDBETWEEN(DATE(2023,1,1),DATE(2025,8,4)),"yyyy-mm-dd") -> 2025-06-07 | G11: ="INSERT INTO tblJobPlacement VALUES (" & B11 & ", " & C11 & ", '" & D11 & "', '" & E11 & "');" -> INSERT INTO tblJobPlacement VALUES (seqJobPlacement.nextval, 174, '취업', '2025-06-07');
B12: seqJobPlacement.nextval | C12: 175 | D12: 취업 | E12: =TEXT(RANDBETWEEN(DATE(2023,1,1),DATE(2025,8,4)),"yyyy-mm-dd") -> 2023-11-22 | G12: ="INSERT INTO tblJobPlacement VALUES (" & B12 & ", " & C12 & ", '" & D12 & "', '" & E12 & "');" -> INSERT INTO tblJobPlacement VALUES (seqJobPlacement.nextval, 175, '취업', '2023-11-22');
B13: seqJobPlacement.nextval | C13: 176 | D13: 취업 | E13: =TEXT(RANDBETWEEN(DATE(2023,1,1),DATE(2025,8,4)),"yyyy-mm-dd") -> 2023-05-05 | G13: ="INSERT INTO tblJobPlacement VALUES (" & B13 & ", " & C13 & ", '" & D13 & "', '" & E13 & "');" -> INSERT INTO tblJobPlacement VALUES (seqJobPlacement.nextval, 176, '취업', '2023-05-05');
B14: seqJobPlacement.nextval | C14: 177 | D14: 취업 | E14: =TEXT(RANDBETWEEN(DATE(2023,1,1),DATE(2025,8,4)),"yyyy-mm-dd") -> 2024-11-05 | G14: ="INSERT INTO tblJobPlacement VALUES (" & B14 & ", " & C14 & ", '" & D14 & "', '" & E14 & "');" -> INSERT INTO tblJobPlacement VALUES (seqJobPlacement.nextval, 177, '취업', '2024-11-05');
B15: seqJobPlacement.nextval | C15: 178 | D15: 취업 | E15: =TEXT(RANDBETWEEN(DATE(2023,1,1),DATE(2025,8,4)),"yyyy-mm-dd") -> 2024-09-11 | G15: ="INSERT INTO tblJobPlacement VALUES (" & B15 & ", " & C15 & ", '" & D15 & "', '" & E15 & "');" -> INSERT INTO tblJobPlacement VALUES (seqJobPlacement.nextval, 178, '취업', '2024-09-11');
B16: seqJobPlacement.nextval | C16: 179 | D16: 미취업 | G16: ="INSERT INTO tblJobPlacement VALUES (" & B16 & ", " & C16 & ", '" & D16 & "', '" & E16 & "');" -> INSERT INTO tblJobPlacement VALUES (seqJobPlacement.nextval, 179, '미취업', '');
B17: seqJobPlacement.nextval | C17: 180 | D17: 취업 | E17: =TEXT(RANDBETWEEN(DATE(2023,1,1),DATE(2025,8,4)),"yyyy-mm-dd") -> 2024-12-06 | G17: ="INSERT INTO tblJobPlacement VALUES (" & B17 & ", " & C17 & ", '" & D17 & "', '" & E17 & "');" -> INSERT INTO tblJobPlacement VALUES (seqJobPlacement.nextval, 180, '취업', '2024-12-06');
B18: seqJobPlacement.nextval | C18: 181 | D18: 취업 | E18: =TEXT(RANDBETWEEN(DATE(2023,1,1),DATE(2025,8,4)),"yyyy-mm-dd") -> 2024-01-15 | G18: ="INSERT INTO tblJobPlacement VALUES (" & B18 & ", " & C18 & ", '" & D18 & "', '" & E18 & "');" -> INSERT INTO tblJobPlacement VALUES (seqJobPlacement.nextval, 181, '취업', '2024-01-15');
B19: seqJobPlacement.nextval | C19: 182 | D19: 취업 | E19: =TEXT(RANDBETWEEN(DATE(2023,1,1),DATE(2025,8,4)),"yyyy-mm-dd") -> 2024-11-30 | G19: ="INSERT INTO tblJobPlacement VALUES (" & B19 & ", " & C19 & ", '" & D19 & "', '" & E19 & "');" -> INSERT INTO tblJobPlacement VALUES (seqJobPlacement.nextval, 182, '취업', '2024-11-30');
B20: seqJobPlacement.nextval | C20: 183 | D20: 취업 | E20: =TEXT(RANDBETWEEN(DATE(2023,1,1),DATE(2025,8,4)),"yyyy-mm-dd") -> 2023-08-14 | G20: ="INSERT INTO tblJobPlacement VALUES (" & B20 & ", " & C20 & ", '" & D20 & "', '" & E20 & "');" -> INSERT INTO tblJobPlacement VALUES (seqJobPlacement.nextval, 183, '취업', '2023-08-14');
B21: seqJobPlacement.nextval | C21: 184 | D21: 취업 | E21: =TEXT(RANDBETWEEN(DATE(2023,1,1),DATE(2025,8,4)),"yyyy-mm-dd") -> 2023-06-11 | G21: ="INSERT INTO tblJobPlacement VALUES (" & B21 & ", " & C21 & ", '" & D21 & "', '" & E21 & "');" -> INSERT INTO tblJobPlacement VALUES (seqJobPlacement.nextval, 184, '취업', '2023-06-11');
B22: seqJobPlacement.nextval | C22: 185 | D22: 취업 | E22: =TEXT(RANDBETWEEN(DATE(2023,1,1),DATE(2025,8,4)),"yyyy-mm-dd") -> 2023-03-05 | G22: ="INSERT INTO tblJobPlacement VALUES (" & B22 & ", " & C22 & ", '" & D22 & "', '" & E22 & "');" -> INSERT INTO tblJobPlacement VALUES (seqJobPlacement.nextval, 185, '취업', '2023-03-05');
B23: seqJobPlacement.nextval | C23: 186 | D23: 취업 | E23: =TEXT(RANDBETWEEN(DATE(2023,1,1),DATE(2025,8,4)),"yyyy-mm-dd") -> 2023-11-15 | G23: ="INSERT INTO tblJobPlacement VALUES (" & B23 & ", " & C23 & ", '" & D23 & "', '" & E23 & "');" -> INSERT INTO tblJobPlacement VALUES (seqJobPlacement.nextval, 186, '취업', '2023-11-15');
B24: seqJobPlacement.nextval | C24: 187 | D24: 취업 | E24: =TEXT(RANDBETWEEN(DATE(2023,1,1),DATE(2025,8,4)),"yyyy-mm-dd") -> 2024-04-12 | G24: ="INSERT INTO tblJobPlacement VALUES (" & B24 & ", " & C24 & ", '" & D24 & "', '" & E24 & "');" -> INSERT INTO tblJobPlacement VALUES (seqJobPlacement.nextval, 187, '취업', '2024-04-12');
B25: seqJobPlacement.nextval | C25: 188 | D25: 취업 | E25: =TEXT(RANDBETWEEN(DATE(2023,1,1),DATE(2025,8,4)),"yyyy-mm-dd") -> 2024-03-10 | G25: ="INSERT INTO tblJobPlacement VALUES (" & B25 & ", " & C25 & ", '" & D25 & "', '" & E25 & "');" -> INSERT INTO tblJobPlacement VALUES (seqJobPlacement.nextval, 188, '취업', '2024-03-10');
B26: seqJobPlacement.nextval | C26: 189 | D26: 취업 | E26: =TEXT(RANDBETWEEN(DATE(2023,1,1),DATE(2025,8,4)),"yyyy-mm-dd") -> 2024-10-12 | G26: ="INSERT INTO tblJobPlacement VALUES (" & B26 & ", " & C26 & ", '" & D26 & "', '" & E26 & "');" -> INSERT INTO tblJobPlacement VALUES (seqJobPlacement.nextval, 189, '취업', '2024-10-12');
B27: seqJobPlacement.nextval | C27: 190 | D27: 취업 | E27: =TEXT(RANDBETWEEN(DATE(2023,1,1),DATE(2025,8,4)),"yyyy-mm-dd") -> 2025-02-22 | G27: ="INSERT INTO tblJobPlacement VALUES (" & B27 & ", " & C27 & ", '" & D27 & "', '" & E27 & "');" -> INSERT INTO tblJobPlacement VALUES (seqJobPlacement.nextval, 190, '취업', '2025-02-22');
B28: seqJobPlacement.nextval | C28: 191 | D28: 취업 | E28: =TEXT(RANDBETWEEN(DATE(2023,1,1),DATE(2025,8,4)),"yyyy-mm-dd") -> 2025-06-26 | G28: ="INSERT INTO tblJobPlacement VALUES (" & B28 & ", " & C28 & ", '" & D28 & "', '" & E28 & "');" -> INSERT INTO tblJobPlacement VALUES (seqJobPlacement.nextval, 191, '취업', '2025-06-26');
B29: seqJobPlacement.nextval | C29: 192 | D29: 미취업 | G29: ="INSERT INTO tblJobPlacement VALUES (" & B29 & ", " & C29 & ", '" & D29 & "', '" & E29 & "');" -> INSERT INTO tblJobPlacement VALUES (seqJobPlacement.nextval, 192, '미취업', '');
B30: seqJobPlacement.nextval | C30: 193 | D30: 취업 | E30: =TEXT(RANDBETWEEN(DATE(2023,1,1),DATE(2025,8,4)),"yyyy-mm-dd") -> 2024-12-28 | G30: ="INSERT INTO tblJobPlacement VALUES (" & B30 & ", " & C30 & ", '" & D30 & "', '" & E30 & "');" -> INSERT INTO tblJobPlacement VALUES (seqJobPlacement.nextval, 193, '취업', '2024-12-28');
B31: seqJobPlacement.nextval | C31: 194 | D31: 취업 | E31: =TEXT(RANDBETWEEN(DATE(2023,1,1),DATE(2025,8,4)),"yyyy-mm-dd") -> 2025-06-24 | G31: ="INSERT INTO tblJobPlacement VALUES (" & B31 & ", " & C31 & ", '" & D31 & "', '" & E31 & "');" -> INSERT INTO tblJobPlacement VALUES (seqJobPlacement.nextval, 194, '취업', '2025-06-24');
B32: seqJobPlacement.nextval | C32: 195 | D32: 취업 | E32: =TEXT(RANDBETWEEN(DATE(2023,1,1),DATE(2025,8,4)),"yyyy-mm-dd") -> 2024-12-22 | G32: ="INSERT INTO tblJobPlacement VALUES (" & B32 & ", " & C32 & ", '" & D32 & "', '" & E32 & "');" -> INSERT INTO tblJobPlacement VALUES (seqJobPlacement.nextval, 195, '취업', '2024-12-22');
